<?xml version="1.0" encoding="utf-8"?>
<!-- from https://github.com/vikashplus/mj_envs/tree/master/mj_envs/hand_manipulation_suite/assets -->
<!-- Information about door can be found in this paper: https://arxiv.org/pdf/1709.10087.pdf -->

<mujoco model="door_lock">
  <asset>
    <texture file="../textures/light-wood.png" type="cube" name="light-wood" />
    <texture file="../textures/dark-wood.png" type="cube" name="dark-wood" />
    <texture file="../textures/brass-ambra.png" type="cube" name="metal" />
    <material name="MatMetal" texture="metal" specular="1" shininess="0.3" rgba="0.9 0.9 0.9 1" />
    <material name="MatDarkWood" texture="dark-wood" texrepeat="3 3" specular="0.4" shininess="0.1" />
    <material name="MatLightWood" texture="light-wood" texrepeat="3 3" specular="0.4" shininess="0.1" />
<!--    <material name="geom" texture="texgeom" texuniform="true"/>-->
  </asset>
    <worldbody>
<!--      <body name="obj1" pos="-0.175 -0.4 -0.4">-->
<!--        <geom conaffinity="1" condim="3" name="obj_geom" pos='-0.175 -0.4 -0.4' density="0.0001" type="box" size=".1 2.3 1.3"  rgba="1 0.5 0.5 .8"/>-->
<!--          <joint axis="1 0 0" damping=".2" name="wall_joint" pos="-0.175 -0.4 -0.4" range="-1 1" stiffness=".0" type="slide"/>-->
<!--      </body>-->

      <body>
<!--        <body name='b1' pos="0.555 0 0" euler='0 0 40'>-->
<!--            <freejoint name="b1_fj"/>-->
<!--            <geom conaffinity="1" condim="3" group="0"  name="wall1" type="box" density=".000001" size="20 10.01 1.7"  material="MatMetal" />-->
<!--        </body>-->
        <body name="object">

          <body name="frame" pos="0 0.22 0" quat="0.707388 0 0 -0.706825">
              <inertial pos="0.3 0 0" quat="0.5 0.5 0.5 0.5" mass="7.85398" diaginertia="0.923301 0.764585 0.168533" />
              <geom size="0.03 0.3" pos="0.555 0 0" type="cylinder" rgba="1 1 1 1" group="0" name="r_frame"/>
              <geom size="0.03 0.3" pos="0.045 0 0" type="cylinder" rgba="1 1 1 1" group="0" name="l_frame"/>
<!--              <geom size="0.03 0.3" pos="-0.175 -0.4 -0.2" type="cylinder" rgba="1 0.1 0.1 1" group="1" name="obstacle_frame"/>-->
              <body name="door" pos="0.3 0 0">
                  <inertial pos="0.0296816 -0.00152345 0" quat="0.701072 0 0 0.713091" mass="2.43455" diaginertia="0.0913751 0.0521615 0.043714" />
                  <joint name="hinge" pos="0.255 0 0" axis="0 0 1" range="0.0 0.4" damping="1" frictionloss="1" limited="true"/>
                  <geom size="0.22 0.02 .29" type="box" friction="1 1 1" group="0" name="panel" rgba="1 1 1 1"  />

<!--                  <body name='panel1' pos="0.3 0 0" >-->
<!--                      <inertial pos="0.0296816 -0.00152345 0" quat="0.701072 0 0 0.713091" mass="2.43455" diaginertia="0.0913751 0.0521615 0.043714" />-->
<!--                      <geom size="0.22 0.02 .29" type="box" friction="1 1 1" group="0" name="panel1" rgba="1 0.1 0.1 1" />-->
<!--                  material="MatDarkWood" rgba="1 0.1 0.1 1"-->
<!--                  </body>-->


<!--                  <geom size="0.0275 0.502215 1.01" pos="-0.175 -0.4 -0.4" type="cylinder" group="0" name="obstacle01" material="MatMetal"/>-->

                  <body name="latch" pos="-0.175 0 -0.025">
                      <inertial pos="-0.017762 0.0138544 0" quat="0.365653 0.605347 -0.36522 0.605365" mass="0.1" diaginertia="0.0483771 0.0410001 0.0111013" />
                      <joint name="latch_joint" pos="0 0 0" axis="0 1 0" range="-1.57 1.57" frictionloss="0.1" damping="0" limited="true" springref="0" stiffness="1" />
                      <geom fromto="0 0.0625 0 0 -0.125 0" size="0.025" type="cylinder" group="0" name="handle_base" material="MatMetal"/>
                      <geom size="0.075 0.015 0.02" pos="0.075 -0.10 0" type="box" group="0" name="handle" material="MatMetal"/>
                      <geom size="0.025 0.0125 0.03125" pos="-0.03125 0.05 0" quat="0.707388 0 0.706825 0" type="box" group="0" name="latch" material="MatMetal"/>
                      <geom size="0.025 0.0125" pos="-0.0625 0.05 0" quat="0.707388 0.706825 0 0" type="cylinder" group="0" name="latch_tip" material="MatMetal"/>
                      <!-- Don't render the door handle site by default -->
                      <site name="handle" pos="0.125 -0.10 0" size="0.02" rgba="0 0 1 0" />
<!--                      <geom size="0.0275 1.02215 1.01" pos="-0.175 -0.4 -0.2" type="cylinder" group="0" name="bottom_site01" material="MatMetal"/>-->
<!--                      <geom name="bottom_site01" pos="0 0 -0.3" group="0" rgba="0.5 0.2 0 0" size="50"/>-->
<!--                      <geom conaffinity="1" condim="3" name="wall1" type="box" density=".000001" size="20 0.01 .7"    rgba="1 0.5 0.5 1"/>-->
                  </body>
              </body>
          </body>
        </body>
        <site name="bottom_site" pos="0 0 -0.3" rgba="0 0 0 0" size="0.005"/>
        <site name="top_site" pos="0 0 0.3" rgba="0 0 0 0" size="0.005"/>
        <site name="horizontal_radius_site" pos="0.3 0 0" rgba="0 0 0 0" size="0.1"/>
<!--          <site name="bottom_site01" pos="0 0 -0.3" rgba="0.5 0.2 0 0" size="50"/>-->
      </body>
<!--        <body name='b1' pos="0.045 0 0" euler='0 0 40'>-->
<!--      <freejoint name="b1_fj"/>-->
<!--      <geom conaffinity="1" condim="3" name="wall1" type="box" density=".000001" size="20 0.01 .7"    rgba="1 0.5 0.5 1"/>-->
<!--    </body>-->

    </worldbody>
</mujoco>